<?xml version="1.0" ?>
<robot xmlns:xacro="http://www.ros.org/wiki/xacro">

<xacro:macro name="padman_right" params="parent prefix *origin">

  <joint name="${prefix}base_joint_right" type="fixed">
    <xacro:insert_block name="origin" />
    <parent link="${parent}"/>
    <child link="${prefix}base_linkMirror" />
  </joint>


<link name="base_linkMirror">
  <inertial>
    <origin xyz="0.019701865393417787 0.014594904935575278 2.8934188281540232e-05" rpy="0 0 0"/>
    <mass value="0.13178098360559276"/>
    <inertia ixx="4.787606446432066e-05" iyy="0.0001444924538761808" izz="0.0001320895098259923" ixy="-2.645567939358464e-05" iyz="5.351316807470616e-08" ixz="7.016390270453513e-08"/>
  </inertial>
  <visual>
    <origin xyz="0 0 0" rpy="0 0 0"/>
    <geometry>
      <mesh filename="file://$(find padman_hw)/urdf/meshes/base_linkMirror.stl" scale="0.001 0.001 0.001"/>
    </geometry>
    <material name="silver"/>
    <material/>
  </visual>
  <collision>
    <origin xyz="0 0 0" rpy="0 0 0"/>
    <geometry>
      <mesh filename="file://$(find padman_hw)/urdf/meshes/base_linkMirror.stl" scale="0.001 0.001 0.001"/>
    </geometry>
  </collision>
</link>

<link name="link0Mirror1">
  <inertial>
    <origin xyz="-6.312709079109302e-05 0.04256997206013418 -0.017691828868565584" rpy="0 0 0"/>
    <mass value="0.4311790263187446"/>
    <inertia ixx="0.0003749971626902564" iyy="0.00019440975860486056" izz="0.0003308969666292287" ixy="7.457801075479165e-08" iyz="5.534815314142672e-05" ixz="3.70565061153438e-07"/>
  </inertial>
  <visual>
    <origin xyz="-0.05375 -0.036 -0.0" rpy="0 0 0"/>
    <geometry>
      <mesh filename="file://$(find padman_hw)/urdf/meshes/link0Mirror1.stl" scale="0.001 0.001 0.001"/>
    </geometry>
    <material name="silver"/>
    <material/>
  </visual>
  <collision>
    <origin xyz="-0.05375 -0.036 -0.0" rpy="0 0 0"/>
    <geometry>
      <mesh filename="file://$(find padman_hw)/urdf/meshes/link0Mirror1.stl" scale="0.001 0.001 0.001"/>
    </geometry>
  </collision>
</link>

<link name="link1Mirror1">
  <inertial>
    <origin xyz="-0.0012541291157318196 0.08016024395860367 -0.02121945021900131" rpy="0 0 0"/>
    <mass value="0.10567997531810189"/>
    <inertia ixx="0.00019254087217471672" iyy="3.642804609956061e-05" izz="0.00020483238099001325" ixy="4.987175372331591e-06" iyz="3.2358619491903214e-05" ixz="-1.494354940325337e-06"/>
  </inertial>
  <visual>
    <origin xyz="-0.05375 -0.124937 0.043887" rpy="0 0 0"/>
    <geometry>
      <mesh filename="file://$(find padman_hw)/urdf/meshes/link1Mirror1.stl" scale="0.001 0.001 0.001"/>
    </geometry>
    <material name="silver"/>
    <material/>
  </visual>
  <collision>
    <origin xyz="-0.05375 -0.124937 0.043887" rpy="0 0 0"/>
    <geometry>
      <mesh filename="file://$(find padman_hw)/urdf/meshes/link1Mirror1.stl" scale="0.001 0.001 0.001"/>
    </geometry>
  </collision>
</link>

<link name="link2Mirror2">
  <inertial>
    <origin xyz="-0.008402041055745532 0.02869107330371176 -0.0025682423626749717" rpy="0 0 0"/>
    <mass value="0.003691660255753207"/>
    <inertia ixx="2.2986267383965026e-06" iyy="3.0790963249513676e-07" izz="2.5900285300856974e-06" ixy="6.376445055931963e-07" iyz="-7.224911525847326e-09" ixz="2.1157477741508437e-09"/>
  </inertial>
  <visual>
    <origin xyz="-0.051457 -0.224911 0.081614" rpy="0 0 0"/>
    <geometry>
      <mesh filename="file://$(find padman_hw)/urdf/meshes/link2Mirror2.stl" scale="0.001 0.001 0.001"/>
    </geometry>
    <material name="silver"/>
    <material/>
  </visual>
  <collision>
    <origin xyz="-0.051457 -0.224911 0.081614" rpy="0 0 0"/>
    <geometry>
      <mesh filename="file://$(find padman_hw)/urdf/meshes/link2Mirror2.stl" scale="0.001 0.001 0.001"/>
    </geometry>
  </collision>
</link>

<link name="ee_r">
  <inertial>
    <origin xyz="0.068058 -0.24335 -0.066126" rpy="0 0 0"/>
    <mass value="0.0"/>
    <inertia ixx="0.0" iyy="0.0" izz="0.0" ixy="0.0" iyz="0.0" ixz="0.0"/>
  </inertial>
  <visual>
    <origin xyz="0.068058 -0.24335 -0.066126" rpy="0 0 0"/>
    <geometry>
      <mesh filename="file://$(find padman_hw)/urdf/meshes/ee1.stl" scale="0.001 0.001 0.001"/>
    </geometry>
    <material name="silver"/>
    <material/>
  </visual>
  <collision>
    <origin xyz="0.068058 -0.24335 -0.066126" rpy="0 0 0"/>
    <geometry>
      <mesh filename="file://$(find padman_hw)/urdf/meshes/ee1.stl" scale="0.001 0.001 0.001"/>
    </geometry>
  </collision>
</link>

<joint name="ee_rigid_r" type="fixed">
  <origin xyz="-0.0219 0.0821 0.0" rpy="0 0 0"/>
  <parent link="link2Mirror2"/>
  <child link="ee_r"/>
</joint>

<joint name="joint1_r" type="revolute">
  <origin xyz="0.05375 0.036 0.0" rpy="0 0 0"/>
  <parent link="base_linkMirror"/>
  <child link="link0Mirror1"/>
  <axis xyz="0.0 1.0 0.0"/>
  <limit upper="1.047198" lower="-2.094395" effort="100" velocity="100"/>
</joint>
<transmission name="Revolute_12_tran">
  <type>transmission_interface/SimpleTransmission</type>
  <joint name="Revolute_12">
    <hardwareInterface>PositionJointInterface</hardwareInterface>
  </joint>
  <actuator name="Revolute_12_actr">
    <hardwareInterface>PositionJointInterface</hardwareInterface>
    <mechanicalReduction>1</mechanicalReduction>
  </actuator>
</transmission>

<joint name="joint2_r" type="revolute">
  <origin xyz="0.0 0.088937 -0.043887" rpy="0 0 0"/>
  <parent link="link0Mirror1"/>
  <child link="link1Mirror1"/>
  <axis xyz="0.0 0.0 -1.0"/>
  <limit upper="1.047198" lower="-2.094395" effort="100" velocity="100"/>
</joint>
<transmission name="Revolute_13_tran">
  <type>transmission_interface/SimpleTransmission</type>
  <joint name="Revolute_13">
    <hardwareInterface>PositionJointInterface</hardwareInterface>
  </joint>
  <actuator name="Revolute_13_actr">
    <hardwareInterface>PositionJointInterface</hardwareInterface>
    <mechanicalReduction>1</mechanicalReduction>
  </actuator>
</transmission>

<joint name="joint3_r" type="revolute">
  <origin xyz="-0.002293 0.099974 -0.037727" rpy="0 0 0"/>
  <parent link="link1Mirror1"/>
  <child link="link2Mirror2"/>
  <axis xyz="0.0 0.0 -1.0"/>
  <limit upper="1.047198" lower="-2.094395" effort="100" velocity="100"/>
</joint>
<transmission name="Revolute_14_tran">
  <type>transmission_interface/SimpleTransmission</type>
  <joint name="Revolute_14">
    <hardwareInterface>PositionJointInterface</hardwareInterface>
  </joint>
  <actuator name="Revolute_14_actr">
    <hardwareInterface>PositionJointInterface</hardwareInterface>
    <mechanicalReduction>1</mechanicalReduction>
  </actuator>
</transmission>

</xacro:macro>

</robot>
