<?xml version="1.0" ?>
<!-- =================================================================================== -->
<!-- |    This document was autogenerated by xacro from padman.urdf.xacro              | -->
<!-- |    EDITING THIS FILE BY HAND IS NOT RECOMMENDED                                 | -->
<!-- =================================================================================== -->
<robot name="padman_robot">
  <!-- Import Rviz colors -->
  <!--<xacro:include filename="$(find padman_hw)/padman/urdf/padman.materials.xacro" />-->
  <!-- Used for fixing robot -->
  <link name="world"/>
  <joint name="base_joint" type="fixed">
    <origin rpy="0 0 0" xyz="0 0 0"/>
    <parent link="world"/>
    <child link="base_link"/>
  </joint>
  <material name="silver">
    <color rgba="0.700 0.700 0.700 1.000"/>
  </material>
  <link name="base_link">
    <inertial>
      <origin rpy="0 0 0" xyz="-0.019701865193031222 0.014594906227722188 2.893676937519002e-05"/>
      <mass value="0.13178100902638776"/>
      <inertia ixx="4.787607624587333e-05" ixy="2.6455679576127112e-05" ixz="-7.016308584896322e-08" iyy="0.00014449246710482235" iyz="5.351212950954777e-08" izz="0.00013208951594725291"/>
    </inertial>
    <visual>
      <origin rpy="0 0 0" xyz="0 0 0"/>
      <geometry>
        <mesh filename="file:///home/manuelbaum/ws_control/install/padman_hw/share/padman_hw/urdf/meshes/base_link.stl" scale="0.001 0.001 0.001"/>
      </geometry>
      <material name="silver"/>
      <material/>
    </visual>
    <collision>
      <origin rpy="0 0 0" xyz="0 0 0"/>
      <geometry>
        <mesh filename="file:///home/manuelbaum/ws_control/install/padman_hw/share/padman_hw/urdf/meshes/base_link.stl" scale="0.001 0.001 0.001"/>
      </geometry>
    </collision>
  </link>
  <link name="link11">
    <inertial>
      <origin rpy="0 0 0" xyz="0.0012541291157320417 0.08016024395860351 -0.02121945021900124"/>
      <mass value="0.10567997531810187"/>
      <inertia ixx="0.0001925408721747254" ixy="-4.987175372334627e-06" ixz="1.4943549403268548e-06" iyy="3.642804609956375e-05" iyz="3.2358619491903e-05" izz="0.00020483238099002713"/>
    </inertial>
    <visual>
      <origin rpy="0 0 0" xyz="0.05375 -0.124937 0.043887"/>
      <geometry>
        <mesh filename="file:///home/manuelbaum/ws_control/install/padman_hw/share/padman_hw/urdf/meshes/link11.stl" scale="0.001 0.001 0.001"/>
      </geometry>
      <material name="silver"/>
      <material/>
    </visual>
    <collision>
      <origin rpy="0 0 0" xyz="0.05375 -0.124937 0.043887"/>
      <geometry>
        <mesh filename="file:///home/manuelbaum/ws_control/install/padman_hw/share/padman_hw/urdf/meshes/link11.stl" scale="0.001 0.001 0.001"/>
      </geometry>
    </collision>
  </link>
  <link name="link01">
    <inertial>
      <origin rpy="0 0 0" xyz="6.31794486038173e-05 0.04256990962300463 -0.017692065640363085"/>
      <mass value="0.4311830367962218"/>
      <inertia ixx="0.00037499959872605527" ixy="-7.4221521683673e-08" ixz="-3.6999575596391313e-07" iyy="0.0001944126429888947" iyz="5.5347540716610996e-05" izz="0.0003308967395141962"/>
    </inertial>
    <visual>
      <origin rpy="0 0 0" xyz="0.05375 -0.036 -0.0"/>
      <geometry>
        <mesh filename="file:///home/manuelbaum/ws_control/install/padman_hw/share/padman_hw/urdf/meshes/link01.stl" scale="0.001 0.001 0.001"/>
      </geometry>
      <material name="silver"/>
      <material/>
    </visual>
    <collision>
      <origin rpy="0 0 0" xyz="0.05375 -0.036 -0.0"/>
      <geometry>
        <mesh filename="file:///home/manuelbaum/ws_control/install/padman_hw/share/padman_hw/urdf/meshes/link01.stl" scale="0.001 0.001 0.001"/>
      </geometry>
    </collision>
  </link>
  <link name="link22">
    <inertial>
      <origin rpy="0 0 0" xyz="0.008402041055472424 0.02869107330327006 -0.002568242362726972"/>
      <mass value="0.003691660255751033"/>
      <inertia ixx="2.2986267384571095e-06" ixy="-6.376445057193296e-07" ixz="-2.115747797964328e-09" iyy="3.079096325934942e-07" iyz="-7.224911540795764e-09" izz="2.590028530225451e-06"/>
    </inertial>
    <visual>
      <origin rpy="0 0 0" xyz="0.051457 -0.224911 0.081614"/>
      <geometry>
        <mesh filename="file:///home/manuelbaum/ws_control/install/padman_hw/share/padman_hw/urdf/meshes/link22.stl" scale="0.001 0.001 0.001"/>
      </geometry>
      <material name="silver"/>
      <material/>
    </visual>
    <collision>
      <origin rpy="0 0 0" xyz="0.051457 -0.224911 0.081614"/>
      <geometry>
        <mesh filename="file:///home/manuelbaum/ws_control/install/padman_hw/share/padman_hw/urdf/meshes/link22.stl" scale="0.001 0.001 0.001"/>
      </geometry>
    </collision>
  </link>
  <link name="ee1">
    <inertial>
      <origin rpy="0 0 0" xyz="0.068058 -0.24335 -0.066126"/>
      <mass value="0.0"/>
      <inertia ixx="0.0" ixy="0.0" ixz="0.0" iyy="0.0" iyz="0.0" izz="0.0"/>
    </inertial>
    <visual>
      <origin rpy="0 0 0" xyz="0.068058 -0.24335 -0.066126"/>
      <geometry>
        <mesh filename="file:///home/manuelbaum/ws_control/install/padman_hw/share/padman_hw/urdf/meshes/ee1.stl" scale="0.001 0.001 0.001"/>
      </geometry>
      <material name="silver"/>
      <material/>
    </visual>
    <collision>
      <origin rpy="0 0 0" xyz="0.068058 -0.24335 -0.066126"/>
      <geometry>
        <mesh filename="file:///home/manuelbaum/ws_control/install/padman_hw/share/padman_hw/urdf/meshes/ee1.stl" scale="0.001 0.001 0.001"/>
      </geometry>
    </collision>
  </link>
  <joint name="Rigid_10" type="fixed">
    <origin rpy="0 0 0" xyz="0.0219 0.0821 0.0"/>
    <parent link="link22"/>
    <child link="ee1"/>
  </joint>
  <joint name="joint2_l" type="revolute">
    <origin rpy="0 0 0" xyz="0.0 0.088937 -0.043887"/>
    <parent link="link01"/>
    <child link="link11"/>
    <axis xyz="0.0 -0.0 1.0"/>
    <limit effort="100" lower="-2.094395" upper="1.047198" velocity="100"/>
  </joint>
  <transmission name="joint2_tran">
    <type>transmission_interface/SimpleTransmission</type>
    <joint name="joint2">
      <hardwareInterface>PositionJointInterface</hardwareInterface>
    </joint>
    <actuator name="joint2_actr">
      <hardwareInterface>PositionJointInterface</hardwareInterface>
      <mechanicalReduction>1</mechanicalReduction>
    </actuator>
  </transmission>
  <joint name="joint1_l" type="revolute">
    <origin rpy="0 0 0" xyz="-0.05375 0.036 0.0"/>
    <parent link="base_link"/>
    <child link="link01"/>
    <axis xyz="0.0 -1.0 0.0"/>
    <limit effort="100" lower="-2.094395" upper="1.047198" velocity="100"/>
  </joint>
  <transmission name="joint1_tran">
    <type>transmission_interface/SimpleTransmission</type>
    <joint name="joint1">
      <hardwareInterface>PositionJointInterface</hardwareInterface>
    </joint>
    <actuator name="joint1_actr">
      <hardwareInterface>PositionJointInterface</hardwareInterface>
      <mechanicalReduction>1</mechanicalReduction>
    </actuator>
  </transmission>
  <joint name="joint3_l" type="revolute">
    <origin rpy="0 0 0" xyz="0.002293 0.099974 -0.037727"/>
    <parent link="link11"/>
    <child link="link22"/>
    <axis xyz="0.0 -0.0 1.0"/>
    <limit effort="100" lower="-2.094395" upper="1.047198" velocity="100"/>
  </joint>
  <transmission name="joint3_tran">
    <type>transmission_interface/SimpleTransmission</type>
    <joint name="joint3">
      <hardwareInterface>PositionJointInterface</hardwareInterface>
    </joint>
    <actuator name="joint3_actr">
      <hardwareInterface>PositionJointInterface</hardwareInterface>
      <mechanicalReduction>1</mechanicalReduction>
    </actuator>
  </transmission>
  <joint name="base_joint_right" type="fixed">
    <origin rpy="0 0 0" xyz="0.165 0 0"/>
    <parent link="base_link"/>
    <child link="base_linkMirror"/>
  </joint>
  <link name="base_linkMirror">
    <inertial>
      <origin rpy="0 0 0" xyz="0.019701865393417787 0.014594904935575278 2.8934188281540232e-05"/>
      <mass value="0.13178098360559276"/>
      <inertia ixx="4.787606446432066e-05" ixy="-2.645567939358464e-05" ixz="7.016390270453513e-08" iyy="0.0001444924538761808" iyz="5.351316807470616e-08" izz="0.0001320895098259923"/>
    </inertial>
    <visual>
      <origin rpy="0 0 0" xyz="0 0 0"/>
      <geometry>
        <mesh filename="file:///home/manuelbaum/ws_control/install/padman_hw/share/padman_hw/urdf/meshes/base_linkMirror.stl" scale="0.001 0.001 0.001"/>
      </geometry>
      <material name="silver"/>
      <material/>
    </visual>
    <collision>
      <origin rpy="0 0 0" xyz="0 0 0"/>
      <geometry>
        <mesh filename="file:///home/manuelbaum/ws_control/install/padman_hw/share/padman_hw/urdf/meshes/base_linkMirror.stl" scale="0.001 0.001 0.001"/>
      </geometry>
    </collision>
  </link>
  <link name="link0Mirror1">
    <inertial>
      <origin rpy="0 0 0" xyz="-6.312709079109302e-05 0.04256997206013418 -0.017691828868565584"/>
      <mass value="0.4311790263187446"/>
      <inertia ixx="0.0003749971626902564" ixy="7.457801075479165e-08" ixz="3.70565061153438e-07" iyy="0.00019440975860486056" iyz="5.534815314142672e-05" izz="0.0003308969666292287"/>
    </inertial>
    <visual>
      <origin rpy="0 0 0" xyz="-0.05375 -0.036 -0.0"/>
      <geometry>
        <mesh filename="file:///home/manuelbaum/ws_control/install/padman_hw/share/padman_hw/urdf/meshes/link0Mirror1.stl" scale="0.001 0.001 0.001"/>
      </geometry>
      <material name="silver"/>
      <material/>
    </visual>
    <collision>
      <origin rpy="0 0 0" xyz="-0.05375 -0.036 -0.0"/>
      <geometry>
        <mesh filename="file:///home/manuelbaum/ws_control/install/padman_hw/share/padman_hw/urdf/meshes/link0Mirror1.stl" scale="0.001 0.001 0.001"/>
      </geometry>
    </collision>
  </link>
  <link name="link1Mirror1">
    <inertial>
      <origin rpy="0 0 0" xyz="-0.0012541291157318196 0.08016024395860367 -0.02121945021900131"/>
      <mass value="0.10567997531810189"/>
      <inertia ixx="0.00019254087217471672" ixy="4.987175372331591e-06" ixz="-1.494354940325337e-06" iyy="3.642804609956061e-05" iyz="3.2358619491903214e-05" izz="0.00020483238099001325"/>
    </inertial>
    <visual>
      <origin rpy="0 0 0" xyz="-0.05375 -0.124937 0.043887"/>
      <geometry>
        <mesh filename="file:///home/manuelbaum/ws_control/install/padman_hw/share/padman_hw/urdf/meshes/link1Mirror1.stl" scale="0.001 0.001 0.001"/>
      </geometry>
      <material name="silver"/>
      <material/>
    </visual>
    <collision>
      <origin rpy="0 0 0" xyz="-0.05375 -0.124937 0.043887"/>
      <geometry>
        <mesh filename="file:///home/manuelbaum/ws_control/install/padman_hw/share/padman_hw/urdf/meshes/link1Mirror1.stl" scale="0.001 0.001 0.001"/>
      </geometry>
    </collision>
  </link>
  <link name="link2Mirror2">
    <inertial>
      <origin rpy="0 0 0" xyz="-0.008402041055745532 0.02869107330371176 -0.0025682423626749717"/>
      <mass value="0.003691660255753207"/>
      <inertia ixx="2.2986267383965026e-06" ixy="6.376445055931963e-07" ixz="2.1157477741508437e-09" iyy="3.0790963249513676e-07" iyz="-7.224911525847326e-09" izz="2.5900285300856974e-06"/>
    </inertial>
    <visual>
      <origin rpy="0 0 0" xyz="-0.051457 -0.224911 0.081614"/>
      <geometry>
        <mesh filename="file:///home/manuelbaum/ws_control/install/padman_hw/share/padman_hw/urdf/meshes/link2Mirror2.stl" scale="0.001 0.001 0.001"/>
      </geometry>
      <material name="silver"/>
      <material/>
    </visual>
    <collision>
      <origin rpy="0 0 0" xyz="-0.051457 -0.224911 0.081614"/>
      <geometry>
        <mesh filename="file:///home/manuelbaum/ws_control/install/padman_hw/share/padman_hw/urdf/meshes/link2Mirror2.stl" scale="0.001 0.001 0.001"/>
      </geometry>
    </collision>
  </link>
  <link name="ee_r">
    <inertial>
      <origin rpy="0 0 0" xyz="0.068058 -0.24335 -0.066126"/>
      <mass value="0.0"/>
      <inertia ixx="0.0" ixy="0.0" ixz="0.0" iyy="0.0" iyz="0.0" izz="0.0"/>
    </inertial>
    <visual>
      <origin rpy="0 0 0" xyz="0.068058 -0.24335 -0.066126"/>
      <geometry>
        <mesh filename="file:///home/manuelbaum/ws_control/install/padman_hw/share/padman_hw/urdf/meshes/ee1.stl" scale="0.001 0.001 0.001"/>
      </geometry>
      <material name="silver"/>
      <material/>
    </visual>
    <collision>
      <origin rpy="0 0 0" xyz="0.068058 -0.24335 -0.066126"/>
      <geometry>
        <mesh filename="file:///home/manuelbaum/ws_control/install/padman_hw/share/padman_hw/urdf/meshes/ee1.stl" scale="0.001 0.001 0.001"/>
      </geometry>
    </collision>
  </link>
  <joint name="ee_rigid_r" type="fixed">
    <origin rpy="0 0 0" xyz="-0.0219 0.0821 0.0"/>
    <parent link="link2Mirror2"/>
    <child link="ee_r"/>
  </joint>
  <joint name="joint1_r" type="revolute">
    <origin rpy="0 0 0" xyz="0.05375 0.036 0.0"/>
    <parent link="base_linkMirror"/>
    <child link="link0Mirror1"/>
    <axis xyz="0.0 1.0 0.0"/>
    <limit effort="100" lower="-2.094395" upper="1.047198" velocity="100"/>
  </joint>
  <transmission name="Revolute_12_tran">
    <type>transmission_interface/SimpleTransmission</type>
    <joint name="Revolute_12">
      <hardwareInterface>PositionJointInterface</hardwareInterface>
    </joint>
    <actuator name="Revolute_12_actr">
      <hardwareInterface>PositionJointInterface</hardwareInterface>
      <mechanicalReduction>1</mechanicalReduction>
    </actuator>
  </transmission>
  <joint name="joint2_r" type="revolute">
    <origin rpy="0 0 0" xyz="0.0 0.088937 -0.043887"/>
    <parent link="link0Mirror1"/>
    <child link="link1Mirror1"/>
    <axis xyz="0.0 0.0 -1.0"/>
    <limit effort="100" lower="-2.094395" upper="1.047198" velocity="100"/>
  </joint>
  <transmission name="Revolute_13_tran">
    <type>transmission_interface/SimpleTransmission</type>
    <joint name="Revolute_13">
      <hardwareInterface>PositionJointInterface</hardwareInterface>
    </joint>
    <actuator name="Revolute_13_actr">
      <hardwareInterface>PositionJointInterface</hardwareInterface>
      <mechanicalReduction>1</mechanicalReduction>
    </actuator>
  </transmission>
  <joint name="joint3_r" type="revolute">
    <origin rpy="0 0 0" xyz="-0.002293 0.099974 -0.037727"/>
    <parent link="link1Mirror1"/>
    <child link="link2Mirror2"/>
    <axis xyz="0.0 0.0 -1.0"/>
    <limit effort="100" lower="-2.094395" upper="1.047198" velocity="100"/>
  </joint>
  <transmission name="Revolute_14_tran">
    <type>transmission_interface/SimpleTransmission</type>
    <joint name="Revolute_14">
      <hardwareInterface>PositionJointInterface</hardwareInterface>
    </joint>
    <actuator name="Revolute_14_actr">
      <hardwareInterface>PositionJointInterface</hardwareInterface>
      <mechanicalReduction>1</mechanicalReduction>
    </actuator>
  </transmission>
  <ros2_control name="Padman" type="system">
    <hardware>
      <plugin>padman_hw/PadmanSystemPositionOnlyHardware</plugin>
      <param name="example_param_hw_start_duration_sec">0</param>
      <param name="example_param_hw_stop_duration_sec">3.0</param>
      <param name="example_param_hw_slowdown">100</param>
    </hardware>
    <joint name="joint1_l">
      <command_interface name="position">
        <param name="min">-1</param>
        <param name="max">1</param>
      </command_interface>
      <command_interface name="effort">
        <param name="min">-0.1</param>
        <param name="max">0.1</param>
      </command_interface>
      <state_interface name="position"/>
      <state_interface name="velocity"/>
    </joint>
    <joint name="joint2_l">
      <command_interface name="position">
        <param name="min">-1</param>
        <param name="max">1</param>
      </command_interface>
      <command_interface name="effort">
        <param name="min">-0.1</param>
        <param name="max">0.1</param>
      </command_interface>
      <state_interface name="position"/>
      <state_interface name="velocity"/>
    </joint>
    <joint name="joint3_l">
      <command_interface name="position">
        <param name="min">-1</param>
        <param name="max">1</param>
      </command_interface>
      <command_interface name="effort">
        <param name="min">-0.1</param>
        <param name="max">0.1</param>
      </command_interface>
      <state_interface name="position"/>
      <state_interface name="velocity"/>
    </joint>
    <joint name="joint1_r">
      <command_interface name="position">
        <param name="min">-1</param>
        <param name="max">1</param>
      </command_interface>
      <command_interface name="effort">
        <param name="min">-0.1</param>
        <param name="max">0.1</param>
      </command_interface>
      <state_interface name="position"/>
      <state_interface name="velocity"/>
    </joint>
    <joint name="joint2_r">
      <command_interface name="position">
        <param name="min">-1</param>
        <param name="max">1</param>
      </command_interface>
      <command_interface name="effort">
        <param name="min">-0.1</param>
        <param name="max">0.1</param>
      </command_interface>
      <state_interface name="position"/>
      <state_interface name="velocity"/>
    </joint>
    <joint name="joint3_r">
      <command_interface name="position">
        <param name="min">-1</param>
        <param name="max">1</param>
      </command_interface>
      <command_interface name="effort">
        <param name="min">-0.1</param>
        <param name="max">0.1</param>
      </command_interface>
      <state_interface name="position"/>
      <state_interface name="velocity"/>
    </joint>
  </ros2_control>
</robot>
