<?xml version="1.0" ?>
<!-- =================================================================================== -->
<!-- |    This document was autogenerated by xacro from padman.urdf.xacro              | -->
<!-- |    EDITING THIS FILE BY HAND IS NOT RECOMMENDED                                 | -->
<!-- =================================================================================== -->
<robot name="padman_robot">
  <!-- Import Rviz colors -->
  <!--<xacro:include filename="$(find padman_hw)/padman/urdf/padman.materials.xacro" />-->
  <!-- Used for fixing robot -->
  <link name="world"/>
  <joint name="base_joint" type="fixed">
    <origin rpy="0 0 0" xyz="0 0 0"/>
    <parent link="world"/>
    <child link="base_link"/>
  </joint>
  <material name="silver">
    <color rgba="0.700 0.700 0.700 1.000"/>
  </material>
  <link name="base_link">
    <inertial>
      <origin rpy="0 0 0" xyz="-0.0445773944082032 0.02473072393390289 -4.128825430559362e-06"/>
      <mass value="0.6868164549052079"/>
      <inertia ixx="0.0003675861155112072" ixy="0.00010127478099521061" ixz="1.4328247463185812e-07" iyy="0.000874031459415454" iyz="-7.555673250524021e-08" izz="0.0006393691553661428"/>
    </inertial>
    <visual>
      <origin rpy="0 0 0" xyz="0 0 0"/>
      <geometry>
        <mesh filename="file:///home/manuelbaum/ws_control/install/padman_hw/share/padman_hw/urdf/meshes/base_link.stl" scale="0.001 0.001 0.001"/>
      </geometry>
      <material name="silver"/>
      <material/>
    </visual>
    <collision>
      <origin rpy="0 0 0" xyz="0 0 0"/>
      <geometry>
        <mesh filename="file:///home/manuelbaum/ws_control/install/padman_hw/share/padman_hw/urdf/meshes/base_link.stl" scale="0.001 0.001 0.001"/>
      </geometry>
    </collision>
  </link>
  <link name="link11">
    <inertial>
      <origin rpy="0 0 0" xyz="-0.00924411413412337 0.027048403424114867 -0.009339305887933608"/>
      <mass value="0.6848943201158819"/>
      <inertia ixx="0.0013939100621001288" ixy="0.0003356022671298737" ixz="-4.781817679678493e-05" iyy="0.0004144948312260156" iyz="0.00017050402620067458" izz="0.001708755879647042"/>
    </inertial>
    <visual>
      <origin rpy="0 0 0" xyz="0.05375 -0.124937 0.043887"/>
      <geometry>
        <mesh filename="file:///home/manuelbaum/ws_control/install/padman_hw/share/padman_hw/urdf/meshes/link11.stl" scale="0.001 0.001 0.001"/>
      </geometry>
      <material name="silver"/>
      <material/>
    </visual>
    <collision>
      <origin rpy="0 0 0" xyz="0.05375 -0.124937 0.043887"/>
      <geometry>
        <mesh filename="file:///home/manuelbaum/ws_control/install/padman_hw/share/padman_hw/urdf/meshes/link11.stl" scale="0.001 0.001 0.001"/>
      </geometry>
    </collision>
  </link>
  <link name="link22">
    <inertial>
      <origin rpy="0 0 0" xyz="-3.979861766034709e-06 0.029895466296833845 -0.002568242362725473"/>
      <mass value="0.0635516074729072"/>
      <inertia ixx="4.278516702536754e-05" ixy="5.5577472342187295e-09" ixz="1.769753484384684e-11" iyy="2.086127958728242e-06" iyz="-1.2959951984411328e-07" izz="4.4587113952348004e-05"/>
    </inertial>
    <visual>
      <origin rpy="0 0 0" xyz="0.081005 -0.221152 0.082114"/>
      <geometry>
        <mesh filename="file:///home/manuelbaum/ws_control/install/padman_hw/share/padman_hw/urdf/meshes/link22.stl" scale="0.001 0.001 0.001"/>
      </geometry>
      <material name="silver"/>
      <material/>
    </visual>
    <collision>
      <origin rpy="0 0 0" xyz="0.081005 -0.221152 0.082114"/>
      <geometry>
        <mesh filename="file:///home/manuelbaum/ws_control/install/padman_hw/share/padman_hw/urdf/meshes/link22.stl" scale="0.001 0.001 0.001"/>
      </geometry>
    </collision>
  </link>
  <link name="link01">
    <inertial>
      <origin rpy="0 0 0" xyz="-2.5504578554526314e-05 0.052716154960416366 -0.006200258497213355"/>
      <mass value="1.557417461604787"/>
      <inertia ixx="0.0034232529176621354" ixy="-5.362958937300301e-06" ixz="-1.334863366371855e-06" iyy="0.0017954704957747203" iyz="0.0008653850612075521" izz="0.0027072568417210244"/>
    </inertial>
    <visual>
      <origin rpy="0 0 0" xyz="0.05375 -0.036 -0.0"/>
      <geometry>
        <mesh filename="file:///home/manuelbaum/ws_control/install/padman_hw/share/padman_hw/urdf/meshes/link01.stl" scale="0.001 0.001 0.001"/>
      </geometry>
      <material name="silver"/>
      <material/>
    </visual>
    <collision>
      <origin rpy="0 0 0" xyz="0.05375 -0.036 -0.0"/>
      <geometry>
        <mesh filename="file:///home/manuelbaum/ws_control/install/padman_hw/share/padman_hw/urdf/meshes/link01.stl" scale="0.001 0.001 0.001"/>
      </geometry>
    </collision>
  </link>
  <link name="ee1">
    <inertial>
      <origin rpy="0 0 0" xyz="0.068058 -0.24335 -0.066126"/>
      <mass value="0.0"/>
      <inertia ixx="0.0" ixy="0.0" ixz="0.0" iyy="0.0" iyz="0.0" izz="0.0"/>
    </inertial>
    <visual>
      <origin rpy="0 0 0" xyz="0.068058 -0.24335 -0.066126"/>
      <geometry>
        <mesh filename="file:///home/manuelbaum/ws_control/install/padman_hw/share/padman_hw/urdf/meshes/ee1.stl" scale="0.001 0.001 0.001"/>
      </geometry>
      <material name="silver"/>
      <material/>
    </visual>
    <collision>
      <origin rpy="0 0 0" xyz="0.068058 -0.24335 -0.066126"/>
      <geometry>
        <mesh filename="file:///home/manuelbaum/ws_control/install/padman_hw/share/padman_hw/urdf/meshes/ee1.stl" scale="0.001 0.001 0.001"/>
      </geometry>
    </collision>
  </link>
  <link name="link11gb4106_padman_v71">
    <inertial>
      <origin rpy="0 0 0" xyz="-1.8180410901014188e-05 3.527030868313852e-05 -0.015557279970201461"/>
      <mass value="0.1050227832534516"/>
      <inertia ixx="2.0143933463656442e-05" ixy="2.912641167943271e-08" ixz="1.70405238657809e-08" iyy="2.0102012945655973e-05" iyz="-3.325715240850256e-08" izz="2.958357413317559e-05"/>
    </inertial>
    <visual>
      <origin rpy="0 0 0" xyz="0.081005 -0.221152 0.054887"/>
      <geometry>
        <mesh filename="file:///home/manuelbaum/ws_control/install/padman_hw/share/padman_hw/urdf/meshes/link11gb4106_padman_v71.stl" scale="0.001 0.001 0.001"/>
      </geometry>
      <material name="silver"/>
      <material/>
    </visual>
    <collision>
      <origin rpy="0 0 0" xyz="0.081005 -0.221152 0.054887"/>
      <geometry>
        <mesh filename="file:///home/manuelbaum/ws_control/install/padman_hw/share/padman_hw/urdf/meshes/link11gb4106_padman_v71.stl" scale="0.001 0.001 0.001"/>
      </geometry>
    </collision>
  </link>
  <link name="link01gb2">
    <inertial>
      <origin rpy="0 0 0" xyz="-4.128825434851491e-06 -0.009172208795921968 -0.030230754350487693"/>
      <mass value="0.6868164549052078"/>
      <inertia ixx="0.0006393691553661755" ixy="-1.43282474615071e-07" ixz="7.55567325081731e-08" iyy="0.0003675861155112057" iyz="0.000101274780995217" izz="0.0008740314594154388"/>
    </inertial>
    <visual>
      <origin rpy="0 0 0" xyz="0.05375 -0.124937 0.002387"/>
      <geometry>
        <mesh filename="file:///home/manuelbaum/ws_control/install/padman_hw/share/padman_hw/urdf/meshes/link01gb2.stl" scale="0.001 0.001 0.001"/>
      </geometry>
      <material name="silver"/>
      <material/>
    </visual>
    <collision>
      <origin rpy="0 0 0" xyz="0.05375 -0.124937 0.002387"/>
      <geometry>
        <mesh filename="file:///home/manuelbaum/ws_control/install/padman_hw/share/padman_hw/urdf/meshes/link01gb2.stl" scale="0.001 0.001 0.001"/>
      </geometry>
    </collision>
  </link>
  <joint name="joint2" type="revolute">
    <origin rpy="0 0 0" xyz="0.0 0.0 -0.0415"/>
    <parent link="link01gb2"/>
    <child link="link11"/>
    <axis xyz="0.0 -0.0 1.0"/>
    <limit effort="100" lower="-2.094395" upper="1.047198" velocity="100"/>
  </joint>
  <transmission name="Revolute_4_tran">
    <type>transmission_interface/SimpleTransmission</type>
    <joint name="Revolute_4">
      <hardwareInterface>PositionJointInterface</hardwareInterface>
    </joint>
    <actuator name="Revolute_4_actr">
      <hardwareInterface>PositionJointInterface</hardwareInterface>
      <mechanicalReduction>1</mechanicalReduction>
    </actuator>
  </transmission>
  <joint name="joint3" type="revolute">
    <origin rpy="0 0 0" xyz="0.0 0.0 -0.027227"/>
    <parent link="link11gb4106_padman_v71"/>
    <child link="link22"/>
    <axis xyz="-0.0 0.0 1.0"/>
    <limit effort="100" lower="-2.094395" upper="1.047198" velocity="100"/>
  </joint>
  <transmission name="Revolute_5_tran">
    <type>transmission_interface/SimpleTransmission</type>
    <joint name="Revolute_5">
      <hardwareInterface>PositionJointInterface</hardwareInterface>
    </joint>
    <actuator name="Revolute_5_actr">
      <hardwareInterface>PositionJointInterface</hardwareInterface>
      <mechanicalReduction>1</mechanicalReduction>
    </actuator>
  </transmission>
  <joint name="joint1" type="revolute">
    <origin rpy="0 0 0" xyz="-0.05375 0.036 0.0"/>
    <parent link="base_link"/>
    <child link="link01"/>
    <axis xyz="0.0 1.0 0.0"/>
    <limit effort="100" lower="-2.094395" upper="1.047198" velocity="100"/>
  </joint>
  <transmission name="Revolute_9_tran">
    <type>transmission_interface/SimpleTransmission</type>
    <joint name="Revolute_9">
      <hardwareInterface>PositionJointInterface</hardwareInterface>
    </joint>
    <actuator name="Revolute_9_actr">
      <hardwareInterface>PositionJointInterface</hardwareInterface>
      <mechanicalReduction>1</mechanicalReduction>
    </actuator>
  </transmission>
  <joint name="Rigid_10" type="fixed">
    <origin rpy="0 0 0" xyz="0.0 0.085 0.0"/>
    <parent link="link22"/>
    <child link="ee1"/>
  </joint>
  <joint name="link11_Rigid 1" type="fixed">
    <origin rpy="0 0 0" xyz="-0.027255 0.096215 -0.011"/>
    <parent link="link11"/>
    <child link="link11gb4106_padman_v71"/>
  </joint>
  <joint name="link01_Rigid 1" type="fixed">
    <origin rpy="0 0 0" xyz="0.0 0.088937 -0.002387"/>
    <parent link="link01"/>
    <child link="link01gb2"/>
  </joint>
  <ros2_control name="Padman" type="system">
    <hardware>
      <plugin>padman_hw/PadmanSystemPositionOnlyHardware</plugin>
      <param name="example_param_hw_start_duration_sec">0</param>
      <param name="example_param_hw_stop_duration_sec">3.0</param>
      <param name="example_param_hw_slowdown">100</param>
    </hardware>
    <joint name="joint1">
      <command_interface name="position">
        <param name="min">-1</param>
        <param name="max">1</param>
      </command_interface>
      <command_interface name="effort">
        <param name="min">-0.1</param>
        <param name="max">0.1</param>
      </command_interface>
      <state_interface name="position"/>
    </joint>
    <joint name="joint2">
      <command_interface name="position">
        <param name="min">-1</param>
        <param name="max">1</param>
      </command_interface>
      <command_interface name="effort">
        <param name="min">-0.1</param>
        <param name="max">0.1</param>
      </command_interface>
      <state_interface name="position"/>
    </joint>
    <joint name="joint3">
      <command_interface name="position">
        <param name="min">-1</param>
        <param name="max">1</param>
      </command_interface>
      <command_interface name="effort">
        <param name="min">-0.1</param>
        <param name="max">0.1</param>
      </command_interface>
      <state_interface name="position"/>
    </joint>
  </ros2_control>
</robot>
